Workbook
Name Slicer_Sector: #N/A
Name Slicer_State: #N/A
Name Slicer_Year: #N/A

Sheet Group Dashboard

Sheet Recreated PivotCharts

Sheet Basic Dashboard

Sheet Datasheet
A1: Record Count | B1: Year | C1: State | D1: Sector | E1: CO2 | F1: Population | G1: Land Area (Square Miles) | H1: Water Area (Square Miles)
A2: 1 | B2: 1970 | C2: Alabama | D2: Commercial | E2: =_xlfn.MAXIFS('CO2'!$D:$D,'CO2'!$A:$A,Table1[[#This Row],[Year]],'CO2'!$B:$B,Table1[[#This Row],[State]],'CO2'!$C:$C,Table1[[#This Row],[Sector]]) -> 2.93 | F2: =AVERAGEIFS(Population!$C:$C,Population!$A:$A,Table1[[#This Row],[Year]],Population!$B:$B,Table1[[#This Row],[State]]) -> 3444354 | G2: =_xlfn.MAXIFS('Land and Water Area'!$B:$B,'Land and Water Area'!$A:$A,Datasheet!C2) -> 50650.834 | H2: =_xlfn.MAXIFS('Land and Water Area'!$C:$C,'Land and Water Area'!$A:$A,Datasheet!C2) -> 1769.244
A3: 1 | B3: 1970 | C3: Alabama | D3: Electric power | E3: =_xlfn.MAXIFS('CO2'!$D:$D,'CO2'!$A:$A,Table1[[#This Row],[Year]],'CO2'!$B:$B,Table1[[#This Row],[State]],'CO2'!$C:$C,Table1[[#This Row],[Sector]]) -> 37.34 | F3: =AVERAGEIFS(Population!$C:$C,Population!$A:$A,Table1[[#This Row],[Year]],Population!$B:$B,Table1[[#This Row],[State]]) -> 3444354 | G3: =_xlfn.MAXIFS('Land and Water Area'!$B:$B,'Land and Water Area'!$A:$A,Datasheet!C3) -> 50650.834 | H3: =_xlfn.MAXIFS('Land and Water Area'!$C:$C,'Land and Water Area'!$A:$A,Datasheet!C3) -> 1769.244
A4: 1 | B4: 1970 | C4: Alabama | D4: Industrial | E4: =_xlfn.MAXIFS('CO2'!$D:$D,'CO2'!$A:$A,Table1[[#This Row],[Year]],'CO2'!$B:$B,Table1[[#This Row],[State]],'CO2'!$C:$C,Table1[[#This Row],[Sector]]) -> 39.24 | F4: =AVERAGEIFS(Population!$C:$C,Population!$A:$A,Table1[[#This Row],[Year]],Population!$B:$B,Table1[[#This Row],[State]]) -> 3444354 | G4: =_xlfn.MAXIFS('Land and Water Area'!$B:$B,'Land and Water Area'!$A:$A,Datasheet!C4) -> 50650.834 | H4: =_xlfn.MAXIFS('Land and Water Area'!$C:$C,'Land and Water Area'!$A:$A,Datasheet!C4) -> 1769.244
A5: 1 | B5: 1970 | C5: Alabama | D5: Residential | E5: =_xlfn.MAXIFS('CO2'!$D:$D,'CO2'!$A:$A,Table1[[#This Row],[Year]],'CO2'!$B:$B,Table1[[#This Row],[State]],'CO2'!$C:$C,Table1[[#This Row],[Sector]]) -> 4.34 | F5: =AVERAGEIFS(Population!$C:$C,Population!$A:$A,Table1[[#This Row],[Year]],Population!$B:$B,Table1[[#This Row],[State]]) -> 3444354 | G5: =_xlfn.MAXIFS('Land and Water Area'!$B:$B,'Land and Water Area'!$A:$A,Datasheet!C5) -> 50650.834 | H5: =_xlfn.MAXIFS('Land and Water Area'!$C:$C,'Land and Water Area'!$A:$A,Datasheet!C5) -> 1769.244
A6: 1 | B6: 1970 | C6: Alabama | D6: Transportation | E6: =_xlfn.MAXIFS('CO2'!$D:$D,'CO2'!$A:$A,Table1[[#This Row],[Year]],'CO2'!$B:$B,Table1[[#This Row],[State]],'CO2'!$C:$C,Table1[[#This Row],[Sector]]) -> 18.79 | F6: =AVERAGEIFS(Population!$C:$C,Population!$A:$A,Table1[[#This Row],[Year]],Population!$B:$B,Table1[[#This Row],[State]]) -> 3444354 | G6: =_xlfn.MAXIFS('Land and Water Area'!$B:$B,'Land and Water Area'!$A:$A,Datasheet!C6) -> 50650.834 | H6: =_xlfn.MAXIFS('Land and Water Area'!$C:$C,'Land and Water Area'!$A:$A,Datasheet!C6) -> 1769.244
A7: 1 | B7: 1970 | C7: Alaska | D7: Commercial | E7: =_xlfn.MAXIFS('CO2'!$D:$D,'CO2'!$A:$A,Table1[[#This Row],[Year]],'CO2'!$B:$B,Table1[[#This Row],[State]],'CO2'!$C:$C,Table1[[#This Row],[Sector]]) -> 1.35 | F7: =AVERAGEIFS(Population!$C:$C,Population!$A:$A,Table1[[#This Row],[Year]],Population!$B:$B,Table1[[#This Row],[State]]) -> 302583 | G7: =_xlfn.MAXIFS('Land and Water Area'!$B:$B,'Land and Water Area'!$A:$A,Datasheet!C7) -> 571051.64 | H7: =_xlfn.MAXIFS('Land and Water Area'!$C:$C,'Land and Water Area'!$A:$A,Datasheet!C7) -> 94729.05
A8: 1 | B8: 1970 | C8: Alaska | D8: Electric power | E8: =_xlfn.MAXIFS('CO2'!$D:$D,'CO2'!$A:$A,Table1[[#This Row],[Year]],'CO2'!$B:$B,Table1[[#This Row],[State]],'CO2'!$C:$C,Table1[[#This Row],[Sector]]) -> 1.01 | F8: =AVERAGEIFS(Population!$C:$C,Population!$A:$A,Table1[[#This Row],[Year]],Population!$B:$B,Table1[[#This Row],[State]]) -> 302583 | G8: =_xlfn.MAXIFS('Land and Water Area'!$B:$B,'Land and Water Area'!$A:$A,Datasheet!C8) -> 571051.64 | H8: =_xlfn.MAXIFS('Land and Water Area'!$C:$C,'Land and Water Area'!$A:$A,Datasheet!C8) -> 94729.05
A9: 1 | B9: 1970 | C9: Alaska | D9: Industrial | E9: =_xlfn.MAXIFS('CO2'!$D:$D,'CO2'!$A:$A,Table1[[#This Row],[Year]],'CO2'!$B:$B,Table1[[#This Row],[State]],'CO2'!$C:$C,Table1[[#This Row],[Sector]]) -> 2.9 | F9: =AVERAGEIFS(Population!$C:$C,Population!$A:$A,Table1[[#This Row],[Year]],Population!$B:$B,Table1[[#This Row],[State]]) -> 302583 | G9: =_xlfn.MAXIFS('Land and Water Area'!$B:$B,'Land and Water Area'!$A:$A,Datasheet!C9) -> 571051.64 | H9: =_xlfn.MAXIFS('Land and Water Area'!$C:$C,'Land and Water Area'!$A:$A,Datasheet!C9) -> 94729.05
A10: 1 | B10: 1970 | C10: Alaska | D10: Residential | E10: =_xlfn.MAXIFS('CO2'!$D:$D,'CO2'!$A:$A,Table1[[#This Row],[Year]],'CO2'!$B:$B,Table1[[#This Row],[State]],'CO2'!$C:$C,Table1[[#This Row],[Sector]]) -> 0.96 | F10: =AVERAGEIFS(Population!$C:$C,Population!$A:$A,Table1[[#This Row],[Year]],Population!$B:$B,Table1[[#This Row],[State]]) -> 302583 | G10: =_xlfn.MAXIFS('Land and Water Area'!$B:$B,'Land and Water Area'!$A:$A,Datasheet!C10) -> 571051.64 | H10: =_xlfn.MAXIFS('Land and Water Area'!$C:$C,'Land and Water Area'!$A:$A,Datasheet!C10) -> 94729.05
A11: 1 | B11: 1970 | C11: Alaska | D11: Transportation | E11: =_xlfn.MAXIFS('CO2'!$D:$D,'CO2'!$A:$A,Table1[[#This Row],[Year]],'CO2'!$B:$B,Table1[[#This Row],[State]],'CO2'!$C:$C,Table1[[#This Row],[Sector]]) -> 5.12 | F11: =AVERAGEIFS(Population!$C:$C,Population!$A:$A,Table1[[#This Row],[Year]],Population!$B:$B,Table1[[#This Row],[State]]) -> 302583 | G11: =_xlfn.MAXIFS('Land and Water Area'!$B:$B,'Land and Water Area'!$A:$A,Datasheet!C11) -> 571051.64 | H11: =_xlfn.MAXIFS('Land and Water Area'!$C:$C,'Land and Water Area'!$A:$A,Datasheet!C11) -> 94729.05
A12: 1 | B12: 1970 | C12: Arizona | D12: Commercial | E12: =_xlfn.MAXIFS('CO2'!$D:$D,'CO2'!$A:$A,Table1[[#This Row],[Year]],'CO2'!$B:$B,Table1[[#This Row],[State]],'CO2'!$C:$C,Table1[[#This Row],[Sector]]) -> 1.5 | F12: =AVERAGEIFS(Population!$C:$C,Population!$A:$A,Table1[[#This Row],[Year]],Population!$B:$B,Table1[[#This Row],[State]]) -> 1775399 | G12: =_xlfn.MAXIFS('Land and Water Area'!$B:$B,'Land and Water Area'!$A:$A,Datasheet!C12) -> 113655.39 | H12: =_xlfn.MAXIFS('Land and Water Area'!$C:$C,'Land and Water Area'!$A:$A,Datasheet!C12) -> 329.732
A13: 1 | B13: 1970 | C13: Arizona | D13: Electric power | E13: =_xlfn.MAXIFS('CO2'!$D:$D,'CO2'!$A:$A,Table1[[#This Row],[Year]],'CO2'!$B:$B,Table1[[#This Row],[State]],'CO2'!$C:$C,Table1[[#This Row],[Sector]]) -> 4.13 | F13: =AVERAGEIFS(Population!$C:$C,Population!$A:$A,Table1[[#This Row],[Year]],Population!$B:$B,Table1[[#This Row],[State]]) -> 1775399 | G13: =_xlfn.MAXIFS('Land and Water Area'!$B:$B,'Land and Water Area'!$A:$A,Datasheet!C13) -> 113655.39 | H13: =_xlfn.MAXIFS('Land and Water Area'!$C:$C,'Land and Water Area'!$A:$A,Datasheet!C13) -> 329.732
... A13261: 1 | B13261: 2021 | C13261: Wyoming | D13261: Transportation | E13261: =_xlfn.MAXIFS('CO2'!$D:$D,'CO2'!$A:$A,Table1[[#This Row],[Year]],'CO2'!$B:$B,Table1[[#This Row],[State]],'CO2'!$C:$C,Table1[[#This Row],[Sector]]) -> 7.5 | F13261: =AVERAGEIFS(Population!$C:$C,Population!$A:$A,Table1[[#This Row],[Year]],Population!$B:$B,Table1[[#This Row],[State]]) -> 579548 | G13261: =_xlfn.MAXIFS('Land and Water Area'!$B:$B,'Land and Water Area'!$A:$A,Datasheet!C13261) -> 97088.542 | H13261: =_xlfn.MAXIFS('Land and Water Area'!$C:$C,'Land and Water Area'!$A:$A,Datasheet!C13261) -> 721.261

Sheet CO2 By State
A3: Sum of CO2 | B3: Column Labels
A4: Row Labels | B4: Commercial | C4: Electric power | D4: Industrial | E4: Residential | F4: Transportation | G4: Grand Total
A5: Alabama | B5: 121.02 | C5: 2982.49 | D5: 1336.16 | E5: 162.02 | F5: 1527.98 | G5: 6129.67
A6: Alaska | B6: 115.17 | C6: 134.1 | D6: 738.12 | E6: 79.48 | F6: 585.6 | G6: 1652.47
A7: Arizona | B7: 110.94 | C7: 1850.45 | D7: 252.72 | E7: 107.32 | F7: 1414.88 | G7: 3736.31
A8: Arkansas | B8: 120.2 | C8: 1123.66 | D8: 513.06 | E8: 142.89 | F8: 907.02 | G8: 2806.83
A9: California | B9: 870.74 | C9: 2341.83 | D9: 3587.76 | E9: 1519 | F9: 9736.31 | G9: 18055.64
A10: Colorado | B10: 212.01 | C10: 1571.62 | D10: 546.48 | E10: 338.41 | F10: 1205.95 | G10: 3874.47
A11: Connecticut | B11: 197.3 | C11: 487.91 | D11: 182.47 | E11: 414.13 | F11: 783.75 | G11: 2065.56
A12: Delaware | B12: 46.15 | C12: 292.99 | D12: 198.95 | E12: 61.21 | F12: 238.67 | G12: 837.97
A13: Florida | B13: 275.38 | C13: 4699.49 | D13: 655.64 | E13: 91.71 | F13: 4481.79 | G13: 10204.01
A14: Georgia | B14: 205.02 | C14: 3007.55 | D14: 829.6 | E14: 349.27 | F14: 2726.19 | G14: 7117.63
A15: Hawaii | B15: 20.22 | C15: 326.85 | D15: 84.97 | E15: 3.47 | F15: 533.21 | G15: 968.72
A16: Idaho | B16: 53.32 | C16: 20.2 | D16: 185.94 | E16: 66.9 | F16: 398.71 | G16: 725.07
... A56: Grand Total | B56: 12390.51 | C56: 94328.55 | D56: 55316.05 | E56: 19394.82 | F56: 85545.98 | G56: 266975.91

Sheet CO2 By Sector
A3: Row Labels | B3: Sum of CO2
A4: Commercial | B4: 0.046410592
A5: Electric power | B5: 0.35332233
A6: Industrial | B6: 0.20719491
A7: Residential | B7: 0.07264633
A8: Transportation | B8: 0.32042584
A9: Grand Total | B9: 1

Sheet CO2 By Year
A3: Sum of CO2 | B3: Column Labels
A4: Row Labels | B4: Commercial | C4: Electric power | D4: Industrial | E4: Residential | F4: Transportation | G4: Grand Total
A5: 1970 | B5: 262.44 | C5: 1061.43 | D5: 1321.61 | E5: 477.76 | F5: 1131.69 | G5: 4254.93
A6: 1971 | B6: 266.86 | C6: 1098.84 | D6: 1274.88 | E6: 483.24 | F6: 1176.29 | G6: 4300.11
A7: 1972 | B7: 271.5 | C7: 1191.55 | D7: 1315.51 | E7: 494.99 | F7: 1246.46 | G7: 4520.01
A8: 1973 | B8: 274.04 | C8: 1283.23 | D8: 1372.82 | E8: 474.79 | F8: 1312.12 | G8: 4717
A9: 1974 | B9: 262.23 | C9: 1248.95 | D9: 1305.9 | E9: 450.51 | F9: 1278.15 | G9: 4545.74
A10: 1975 | B10: 247.9 | C10: 1243.5 | D10: 1192.1 | E10: 449.93 | F10: 1288.55 | G10: 4421.98
A11: 1976 | B11: 267.66 | C11: 1351.8 | D11: 1249.15 | E11: 472.55 | F11: 1350.48 | G11: 4691.64
A12: 1977 | B12: 262.88 | C12: 1439.76 | D12: 1266.22 | E12: 458.54 | F12: 1402.88 | G12: 4830.28
A13: 1978 | B13: 264.9 | C13: 1447.36 | D13: 1242.77 | E13: 456.32 | F13: 1460.1 | G13: 4871.45
A14: 1979 | B14: 264.98 | C14: 1508.28 | D14: 1285.01 | E14: 422.91 | F14: 1449.88 | G14: 4931.06
A15: 1980 | B15: 249.38 | C15: 1554.91 | D15: 1172.21 | E15: 385.14 | F15: 1394.86 | G15: 4756.5
A16: 1981 | B16: 232 | C16: 1564.89 | D16: 1096.03 | E16: 359.46 | F16: 1380.6 | G16: 4632.98
... A56: 2021 | B56: 247.92 | C56: 1542.06 | D56: 980.18 | E56: 326.26 | F56: 1814.84 | G56: 4911.26
A57: Grand Total | B57: 12390.51 | C57: 94328.55 | D57: 55316.05 | E57: 19394.82 | F57: 85545.98 | G57: 266975.91

Sheet CO2 By Water
A3: Sum of C02 Water | B3: Column Labels
A4: Row Labels | B4: Commercial | C4: Electric power | D4: Industrial | E4: Residential | F4: Transportation | G4: Grand Total
A5: Alabama | B5: 0.0013154249 | C5: 0.032418127 | D5: 0.01452337 | E5: 0.0017610738 | F5: 0.016608354 | G5: 0.01332527
A6: Alaska | B6: 2.3380449e-05 | C6: 2.7223393e-05 | D6: 0.00014984438 | E6: 1.6135088e-05 | F6: 0.00011888157 | G6: 6.7092976e-05
A7: Arizona | B7: 0.0064702896 | C7: 0.10792273 | D7: 0.014739243 | E7: 0.0062591625 | F7: 0.08251923 | G7: 0.043582131
A8: Arkansas | B8: 0.0019174792 | C8: 0.017925081 | D8: 0.0081845415 | E8: 0.0022794393 | F8: 0.014469151 | G8: 0.0089551385
A9: California | B9: 0.0021372881 | C9: 0.0057481743 | D9: 0.0088063906 | E9: 0.0037284844 | F9: 0.023898407 | G9: 0.0088637489
A10: Colorado | B10: 0.0089054014 | C10: 0.066015315 | D10: 0.02295469 | E10: 0.014214786 | F10: 0.050655482 | G10: 0.032549135
A11: Connecticut | B11: 0.0054102666 | C11: 0.013379236 | D11: 0.0050036054 | E11: 0.011356076 | F11: 0.021491619 | G11: 0.01132816
A12: Delaware | B12: 0.0016427975 | C12: 0.010429539 | D12: 0.0070820057 | E12: 0.002178887 | F12: 0.0084959151 | G12: 0.005965829
A13: Florida | B13: 0.00029836456 | C13: 0.0050917324 | D13: 0.00071036292 | E13: 9.9364564e-05 | F13: 0.0048558621 | G13: 0.0022111373
A14: Georgia | B14: 0.0023104687 | C14: 0.033893523 | D14: 0.0093491601 | E14: 0.0039360911 | F14: 0.030722742 | G14: 0.016042397
A15: Hawaii | B15: 8.5511982e-05 | C15: 0.0013822745 | D15: 0.00035934486 | E15: 1.4674905e-05 | F15: 0.0022549873 | G15: 0.00081935872
A16: Idaho | B16: 0.0011104339 | C16: 0.00042068199 | D16: 0.0038723569 | E16: 0.0013932488 | F16: 0.0083034712 | G16: 0.0030200385
... A56: Grand Total | B56: 0.00088401681 | C56: 0.0067299913 | D56: 0.0039465945 | E56: 0.0013837483 | F56: 0.0061033876 | G56: 0.0038095477

Sheet CO2 By Land
A3: Sum of CO2 Land | B3: Column Labels
A4: Row Labels | B4: Commercial | C4: Electric power | D4: Industrial | E4: Residential | F4: Transportation | G4: Grand Total
A5: Alabama | B5: 4.5948063e-05 | C5: 0.0011323718 | D5: 0.00050730427 | E5: 6.1514668e-05 | F5: 0.00058013321 | G5: 0.00046545441
A6: Alaska | B6: 3.8784718e-06 | C6: 4.5159596e-06 | D6: 2.4856973e-05 | E6: 2.6765732e-06 | F6: 1.9720701e-05 | G6: 1.1129736e-05
A7: Arizona | B7: 1.8771318e-05 | C7: 0.00031310065 | D7: 4.2760839e-05 | E7: 1.8158805e-05 | F7: 0.00023940114 | G7: 0.00012643855
A8: Arkansas | B8: 4.4458903e-05 | C8: 0.00041561307 | D8: 0.00018976776 | E8: 5.2851353e-05 | F8: 0.00033548348 | G8: 0.00020763491
A9: California | B9: 0.00010743675 | C9: 0.00028894804 | D9: 0.00044267782 | E9: 0.00018742268 | F9: 0.0012013202 | G9: 0.0004455611
A10: Colorado | B10: 3.9340321e-05 | C10: 0.00029162792 | D10: 0.00010140417 | E10: 6.2794954e-05 | F10: 0.00022377463 | G10: 0.0001437884
A11: Connecticut | B11: 0.00078354393 | C11: 0.0019376529 | D11: 0.00072464907 | E11: 0.001644648 | F11: 0.003112532 | G11: 0.0016406052
A12: Delaware | B12: 0.00045546829 | C12: 0.0028916068 | D12: 0.0019634976 | E12: 0.00060409998 | F12: 0.0023555063 | G12: 0.0016540358
A13: Florida | B13: 9.8701838e-05 | C13: 0.0016843936 | D13: 0.00023499482 | E13: 3.2870744e-05 | F13: 0.0016063654 | G13: 0.00073146528
A14: Georgia | B14: 6.8311234e-05 | C14: 0.0010020947 | D14: 0.00027641693 | E14: 0.00011637433 | F14: 0.00090834749 | G14: 0.00047430893
A15: Hawaii | B15: 6.0543531e-05 | C15: 0.00097866731 | D15: 0.00025442056 | E15: 1.0390012e-05 | F15: 0.0015965587 | G15: 0.00058011601
A16: Idaho | B16: 1.2407079e-05 | C16: 4.7003562e-06 | D16: 4.3266546e-05 | E16: 1.5567021e-05 | F16: 9.2776189e-05 | G16: 3.3743438e-05
... A56: Grand Total | B56: 6.743813e-05 | C56: 0.00051340429 | D56: 0.00030107001 | E56: 0.00010556066 | F56: 0.00046560318 | G56: 0.00029061525

Sheet CO2 By 100K Pop
A3: Sum of CO2 Per Pop | B3: Column Labels
A4: Row Labels | B4: Commercial | C4: Electric power | D4: Industrial | E4: Residential | F4: Transportation | G4: Grand Total
A5: Alabama | B5: 0.054318431 | C5: 1.3386562 | D5: 0.59972 | E5: 0.072720808 | F5: 0.6858162 | G5: 0.55024634
A6: Alaska | B6: 0.38387852 | C6: 0.44697498 | D6: 2.4602623 | E6: 0.26491851 | F6: 1.9518908 | G6: 1.101585
A7: Arizona | B7: 0.046496487 | C7: 0.77554917 | D7: 0.10591844 | E7: 0.044979295 | F7: 0.59299576 | G7: 0.31318783
A8: Arkansas | B8: 0.090414709 | C8: 0.84521957 | D8: 0.38592488 | E8: 0.10748218 | F8: 0.68226248 | G8: 0.42226076
A9: California | B9: 0.053909556 | C9: 0.14498819 | D9: 0.22212664 | E9: 0.094044854 | F9: 0.6027978 | G9: 0.22357341
A10: Colorado | B10: 0.10246795 | C10: 0.75959005 | D10: 0.26412286 | E10: 0.16355917 | F10: 0.58285567 | G10: 0.37451914
A11: Connecticut | B11: 0.11358602 | C11: 0.28089079 | D11: 0.10504835 | E11: 0.23841549 | F11: 0.45120649 | G11: 0.23782943
A12: Delaware | B12: 0.11849365 | C12: 0.7522742 | D12: 0.51081932 | E12: 0.15716135 | F12: 0.61280345 | G12: 0.43031039
A13: Florida | B13: 0.036344461 | C13: 0.62023543 | D13: 0.086530913 | E13: 0.012103822 | F13: 0.59150354 | G13: 0.26934363
A14: Georgia | B14: 0.051858927 | C14: 0.76074684 | D14: 0.20984375 | E14: 0.088346344 | F14: 0.68957803 | G14: 0.36007478
A15: Hawaii | B15: 0.033501038 | C15: 0.54153384 | D15: 0.14078057 | E15: 0.005749189 | F15: 0.88343662 | G15: 0.32100025
A16: Idaho | B16: 0.083219144 | C16: 0.031527132 | D16: 0.29020569 | E16: 0.10441412 | F16: 0.62228629 | G16: 0.22633047
... A56: Grand Total | B56: 0.088752609 | C56: 0.67567073 | D56: 0.39622613 | E56: 0.13892413 | F56: 0.61276162 | G56: 0.38246704

Sheet Land and Water Area by State
A3: Row Labels | B3: Sum of Land Area (Square Miles) | C3: Sum of Water Area (Square Miles)
A4: Alabama | B4: 13169217 | C4: 460003.44
A5: Alaska | B5: 1.4847343e+08 | C5: 24629553
A6: Arizona | B6: 29550402 | C6: 85730.32
A7: Arkansas | B7: 13518102 | C7: 313432.34
A8: California | B8: 40523376 | C8: 2037020.7
A9: Colorado | B9: 26945637 | C9: 119034.5
A10: Connecticut | B10: 1259023.2 | C10: 182338.52
A11: Delaware | B11: 506621.44 | C11: 140461.62
A12: Florida | B12: 13950095 | C12: 4614824.2
A13: Georgia | B13: 15006317 | C13: 443676.22
A14: Hawaii | B14: 1669872.9 | C14: 1182290.5
A15: Idaho | B15: 21487733 | C15: 240086.34
... A55: Grand Total | B55: 9.186576e+08 | C55: 70080737

Sheet Population By State
A3: Row Labels | B3: Sum of Population By State
A4: Alabama | B4: 4284563.5
A5: Alaska | B5: 576955.37
A6: Arizona | B6: 4588436
A7: Arkansas | B7: 2556595.6
A8: California | B8: 31061283
A9: Colorado | B9: 3978917.5
A10: Connecticut | B10: 3340403.1
A11: Delaware | B11: 748985.29
A12: Florida | B12: 14571049
A13: Georgia | B13: 7602726.3
A14: Hawaii | B14: 1160698.8
A15: Idaho | B15: 1232149.9
... A55: Grand Total | B55: 5264226.1

Sheet CO2
A1: Year | B1: State | C1: Sector | D1: CO2 (million metric tons)
A2: 1970 | B2: Alabama | C2: Commercial | D2: 2.93
A3: 1971 | B3: Alabama | C3: Commercial | D3: 2.92
A4: 1972 | B4: Alabama | C4: Commercial | D4: 3.07
A5: 1973 | B5: Alabama | C5: Commercial | D5: 2.92
A6: 1974 | B6: Alabama | C6: Commercial | D6: 2.84
A7: 1975 | B7: Alabama | C7: Commercial | D7: 2.67
A8: 1976 | B8: Alabama | C8: Commercial | D8: 2.9
A9: 1977 | B9: Alabama | C9: Commercial | D9: 2.94
A10: 1978 | B10: Alabama | C10: Commercial | D10: 2.89
A11: 1979 | B11: Alabama | C11: Commercial | D11: 3.04
A12: 1980 | B12: Alabama | C12: Commercial | D12: 2.63
A13: 1981 | B13: Alabama | C13: Commercial | D13: 2.41
... A13261: 2021 | B13261: Wyoming | C13261: Transportation | D13261: 7.5

Sheet Population
A1: Year | B1: State | C1: Population
A2: 1900 | B2: Alabama | C2: 1830000
A3: 1901 | B3: Alabama | C3: 1907000
A4: 1902 | B4: Alabama | C4: 1935000
A5: 1903 | B5: Alabama | C5: 1957000
A6: 1904 | B6: Alabama | C6: 1978000
A7: 1905 | B7: Alabama | C7: 2012000
A8: 1906 | B8: Alabama | C8: 2045000
A9: 1907 | B9: Alabama | C9: 2058000
A10: 1908 | B10: Alabama | C10: 2070000
A11: 1909 | B11: Alabama | C11: 2108000
A12: 1910 | B12: Alabama | C12: 2150000
A13: 1911 | B13: Alabama | C13: 2185000
... A125: 2023 | B125: Alabama | C125: 5108468
A126: 1900 | B126: Alaska
A127: 1901 | B127: Alaska
A128: 1902 | B128: Alaska
A129: 1903 | B129: Alaska
A130: 1904 | B130: Alaska
A131: 1905 | B131: Alaska
A132: 1906 | B132: Alaska
A133: 1907 | B133: Alaska
A134: 1908 | B134: Alaska
A135: 1909 | B135: Alaska
A136: 1910 | B136: Alaska
A137: 1911 | B137: Alaska
... A175: 1949 | B175: Alaska
A176: 1950 | B176: Alaska | C176: 135000
A177: 1951 | B177: Alaska | C177: 158000
A178: 1952 | B178: Alaska | C178: 189000
A179: 1953 | B179: Alaska | C179: 205000
A180: 1954 | B180: Alaska | C180: 215000
A181: 1955 | B181: Alaska | C181: 222000
A182: 1956 | B182: Alaska | C182: 224000
A183: 1957 | B183: Alaska | C183: 231000
A184: 1958 | B184: Alaska | C184: 224000
A185: 1959 | B185: Alaska | C185: 224000
A186: 1960 | B186: Alaska | C186: 229000
A187: 1961 | B187: Alaska | C187: 238000
... A1241: 2023 | B1241: Georgia | C1241: 11029227
...

Sheet Land and Water Area
A1: State | B1: Land Area (Square Miles) | C1: Water Area (Square Miles)
A2: Alabama | B2: 50650.834 | C2: 1769.244
A3: Alaska | B3: 571051.64 | C3: 94729.05
A4: Arizona | B4: 113655.39 | C4: 329.732
A5: Arkansas | B5: 51992.701 | C5: 1205.509
A6: California | B6: 155859.14 | C6: 7834.695
A7: Colorado | B7: 103637.06 | C7: 457.825
A8: Connecticut | B8: 4842.397 | C8: 701.302
A9: Delaware | B9: 1948.544 | C9: 540.237
A10: Florida | B10: 53654.211 | C10: 17749.324
A11: Georgia | B11: 57716.602 | C11: 1706.447
A12: Hawaii | B12: 6422.588 | C12: 4547.271
A13: Idaho | B13: 82645.128 | C13: 923.409
... A52: Wyoming | B52: 97088.542 | C52: 721.261
